Workbook

Sheet DASHBOARD
A1: 📊 DASHBOARD - PORTFOLIO LOGÍSTICA 2026
A2: ="Atualizado em: "&TEXT(TODAY(),"DD/MM/YYYY") -> Atualizado em: 14/05/YYYY
A4: 📋 TOTAL PROJETOS | B4: =COUNTA(PORTFOLIO_LOGISTICA!A3:A56) -> 54 | C4: 🟢 EM DIA | D4: =COUNTIF(PORTFOLIO_LOGISTICA!J3:J56,"*Em Dia*") -> 32 | E4: 🟡 ATENÇÃO | F4: =COUNTIF(PORTFOLIO_LOGISTICA!J3:J56,"*Atenção*") -> 8 | G4: 🔴 CRÍTICO | H4: =COUNTIF(PORTFOLIO_LOGISTICA!J3:J56,"*Crítico*") -> 2
A6: 📊 DISTRIBUIÇÃO POR STAGE | E6: 📊 DISTRIBUIÇÃO POR PRIORIDADE
A7: Stage | B7: Descrição | C7: Qtd | E7: Prioridade | F7: Cor | G7: Qtd
A8: L0 | B8: Ideia / Conceito | C8: =COUNTIF(PORTFOLIO_LOGISTICA!I3:I56,"L0") -> 10 | E8: Alta | F8: 🔴 | G8: =COUNTIF(PORTFOLIO_LOGISTICA!K3:K56,"Alta") -> 19
A9: L1 | B9: Em Análise / Estudo | C9: =COUNTIF(PORTFOLIO_LOGISTICA!I3:I56,"L1") -> 29 | E9: Média | F9: 🟡 | G9: =COUNTIF(PORTFOLIO_LOGISTICA!K3:K56,"Média") -> 22
A10: L2 | B10: Planejamento | C10: =COUNTIF(PORTFOLIO_LOGISTICA!I3:I56,"L2") -> 9 | E10: Baixa | F10: 🟢 | G10: =COUNTIF(PORTFOLIO_LOGISTICA!K3:K56,"Baixa") -> 1
A11: L3 | B11: Em Execução | C11: =COUNTIF(PORTFOLIO_LOGISTICA!I3:I56,"L3") -> 5 | E11: Não definido | F11: ⚪ | G11: =COUNTIF(PORTFOLIO_LOGISTICA!K3:K56,"") -> 12
A12: L4 | B12: Implantação | C12: =COUNTIF(PORTFOLIO_LOGISTICA!I3:I56,"L4") -> 0
A13: L5 | B13: Concluído | C13: =COUNTIF(PORTFOLIO_LOGISTICA!I3:I56,"L5") -> 0 | E13: 📊 DISTRIBUIÇÃO POR GERÊNCIA
A14: TOTAL | C14: =SUM(C8:C13) -> 53 | E14: Gerência | F14: Resp. | G14: Qtd
E15: Transportes | F15: Ana Ferreira | G15: =COUNTIF(PORTFOLIO_LOGISTICA!D3:D56,"*Transport*") -> 17
A16: ⚠️ ALERTAS DE PRAZO | E16: Desconexão | F16: Carlos Silva | G16: =COUNTIF(PORTFOLIO_LOGISTICA!D3:D56,"*Desconexão*") -> 12
A17: Indicador | B17: Símbolo | C17: Qtd | E17: Estoques | F17: Roberto Lima | G17: =COUNTIF(PORTFOLIO_LOGISTICA!D3:D56,"*Estoque*") -> 10
A18: Atrasados | B18: ⚠️ | C18: =COUNTIF(PORTFOLIO_LOGISTICA!Q3:Q56,"*ATRASADO*") -> 1 | E18: Planejamento | F18: Fernanda Costa | G18: =COUNTIF(PORTFOLIO_LOGISTICA!D3:D56,"*Planejamento*") -> 13
A19: Próximos (<30d) | B19: ⏰ | C19: =COUNTIF(PORTFOLIO_LOGISTICA!Q3:Q56,"*PRÓXIMO*") -> 0
A20: No Prazo | B20: ✅ | C20: =COUNTIF(PORTFOLIO_LOGISTICA!Q3:Q56,"*OK*") -> 50
A22: 💰 INDICADORES FINANCEIROS (R$ MM)
A23: 🎯 Meta 2026 | B23: =SUM(PORTFOLIO_LOGISTICA!N3:N56) -> 26.903918 | C23: 📈 Realizado | D23: =SUM(PORTFOLIO_LOGISTICA!O3:O56) -> 50.521478 | E23: 📊 Saldo | F23: =SUM(PORTFOLIO_LOGISTICA!P3:P56) -> 0.31467547 | G23: % Ating. | H23: =IF(B23=0,0,D23/B23) -> 1.8778484
A25: 🚨 PROJETOS CRÍTICOS / EM ATENÇÃO
A26: (Lista os projetos com Status 'Crítico' ou 'Atenção' para acompanhamento prioritário)
A44: 📊 PIPELINE DE MATURIDADE DOS PROJETOS (STAGE GATE)
A45: Metodologia de acompanhamento do ciclo de vida dos projetos - da ideação até a conclusão
A47: Stage | B47: Ícone | C47: Fase | D47: Qtd | E47: % | F47: Descrição
A48: L0 | B48: 💡 | C48: Ideia / Conceito | D48: =PORTFOLIO_LOGISTICA!F64 -> 10 | E48: =D48/SUM($D$48:$D$53) -> 0.18867925 | F48: Projeto em fase inicial de ideação, sem business case formal
A49: L1 | B49: 🔍 | C49: Em Análise | D49: =PORTFOLIO_LOGISTICA!F65 -> 29 | E49: =D49/SUM($D$48:$D$53) -> 0.54716981 | F49: Business case em construção, análise de viabilidade
A50: L2 | B50: 📋 | C50: Planejamento | D50: =PORTFOLIO_LOGISTICA!F66 -> 9 | E50: =D50/SUM($D$48:$D$53) -> 0.16981132 | F50: Projeto aprovado, definição de escopo e cronograma
A51: L3 | B51: ⚙️ | C51: Em Execução | D51: =PORTFOLIO_LOGISTICA!F67 -> 5 | E51: =D51/SUM($D$48:$D$53) -> 0.094339623 | F51: Atividades em andamento, entregas sendo realizadas
A52: L4 | B52: 🚀 | C52: Implantação | D52: =PORTFOLIO_LOGISTICA!F68 -> 0 | E52: =D52/SUM($D$48:$D$53) -> 0 | F52: Fase de deploy, go-live ou rollout em andamento
A53: L5 | B53: ✅ | C53: Concluído | D53: =PORTFOLIO_LOGISTICA!F69 -> 0 | E53: =D53/SUM($D$48:$D$53) -> 0 | F53: Projeto finalizado, todas as entregas concluídas

Sheet HISTORICO
A1: ID | B1: Status | C1: Data Inicio | D1: Data Fim | E1: Dias no Status
A2: LOG-02 | B2: L1 | C2: 46126 | D2: 46126 | E2: =IF(D2="",TODAY()-C2,D2-C2) -> 0
A3: LOG-02 | B3: L3 | C3: 46126 | E3: =IF(D3="",TODAY()-C3,D3-C3) -> 30
A4: LOG-05 | B4: L2 | C4: 46126 | D4: 46126 | E4: =IF(D4="",TODAY()-C4,D4-C4) -> 0
A5: LOG-05 | B5: L3 | C5: 46126 | E5: =IF(D5="",TODAY()-C5,D5-C5) -> 30
E6: =IF(D6="",TODAY()-C6,D6-C6) -> 46156
E7: =IF(D7="",TODAY()-C7,D7-C7) -> 46156
E8: =IF(D8="",TODAY()-C8,D8-C8) -> 46156
E9: =IF(D9="",TODAY()-C9,D9-C9) -> 46156
E10: =IF(D10="",TODAY()-C10,D10-C10) -> 46156
E11: =IF(D11="",TODAY()-C11,D11-C11) -> 46156
E12: =IF(D12="",TODAY()-C12,D12-C12) -> 46156
E13: =IF(D13="",TODAY()-C13,D13-C13) -> 46156
E14: =IF(D14="",TODAY()-C14,D14-C14) -> 46156
E15: =IF(D15="",TODAY()-C15,D15-C15) -> 46156
E16: =IF(D16="",TODAY()-C16,D16-C16) -> 46156
E17: =IF(D17="",TODAY()-C17,D17-C17) -> 46156
... E55: =IF(D55="",TODAY()-C55,D55-C55) -> 46156

Sheet LISTAS
A1: TIPO | B1: Responsabilidade | C1: Stage | D1: Status | E1: Prioridade
A2: DGP | B2: Execução Operacional | C2: L0 | D2: 🟢 Em Dia | E2: Alta | F2: OPEX
A3: OPEX | B3: Acompanhamento | C3: L1 | D3: 🟡 Atenção | E3: Média | F3: CAPEX
A4: CAPEX | B4: Execução Financeira | C4: L2 | D4: 🔴 Crítico | E4: Baixa | F4: RECEITA
C5: L3 | F5: CUSTO EVITADO
C6: L4
C7: L5

Sheet PORTFOLIO_LOGISTICA
A1: 📊 PORTFOLIO DE PROJETOS LOGÍSTICA 2026 | CLARO
A2: ID | B2: Projeto | C2: Forum | D2: Gerencia | E2: Tipo | F2: Responsabilidade | G2: PMO Responsável | H2: Nome Responsável | I2: Stage | J2: Status | K2: Prioridade | L2: Início | M2: Fim Planejado | N2: Meta 2026 | O2: Realizado+ FCST 2026 | P2: Saldo | Q2: Indicador Prazo | R2: AÇÕES | S2: Observações
A3: =IF(TabelaPortfolio[[#This Row],[Projeto]]<>"","LOG-"&TEXT(ROW()-2,"00"),"") -> LOG-01 | B3: Eficiência Desconexão – RPA Terminais Presos (Carry Over) | C3: DGP / RAI – Estratégico | D3: Desconexão | E3: OPEX | F3: Execução Financeira | G3: Helder | H3: Dino / Diego | I3: L3 | J3: 🟢 Em Dia | K3: Média | L3: 46023 | M3: 46357 | N3: 1.6239368 | O3: 1.8019447 | P3: 0.17800795 | Q3: =IF(M3="","",IF(M3<TODAY(),"⚠️ ATRASADO",IF(M3-TODAY()<30,"⏰ PRÓXIMO","✅ OK"))) -> ✅ OK | R3: 02/04 - Entregue (0,22) | S3: Redução para 28 PAs
A4: =IF(TabelaPortfolio[[#This Row],[Projeto]]<>"","LOG-"&TEXT(ROW()-2,"00"),"") -> LOG-02 | B4: APP Devolução em Loja (Expansão AA) | C4: DGP / RAI – Estratégico | D4: Desconexão | E4: OPEX | F4: Execução Financeira | G4: Helder | H4: Dino / Ismael | I4: L3 | L4: 46023 | M4: 46357 | N4: 2.14551 | O4: 2.163582 | P4: 0.018072 | Q4: =IF(M4="","",IF(M4<TODAY(),"⚠️ ATRASADO",IF(M4-TODAY()<30,"⏰ PRÓXIMO","✅ OK"))) -> ✅ OK | R4: 02/04 - FUP Ismael (0,02)
A5: =IF(TabelaPortfolio[[#This Row],[Projeto]]<>"","LOG-"&TEXT(ROW()-2,"00"),"") -> LOG-03 | B5: S&OP Móvel (Carry Over) | C5: DGP / RAI – Estratégico | D5: Desconexão | E5: OPEX | F5: Execução Financeira | G5: Helder | H5: Helder / Quinete / Raquel | I5: L3 | L5: 46023 | M5: 46357 | N5: 1.6239368 | O5: 1.8019447 | P5: 0.17800795 | Q5: =IF(M5="","",IF(M5<TODAY(),"⚠️ ATRASADO",IF(M5-TODAY()<30,"⏰ PRÓXIMO","✅ OK"))) -> ✅ OK | R5: 09/04 - Calendarizações impactadas por lançamentos IPHONE/SAMSUNG/MOTOROLA | S5: Robô teve alteração do FCST pois inicia captura em Jul/26. Robô não aprovado, em transferência de Verba
A6: =IF(TabelaPortfolio[[#This Row],[Projeto]]<>"","LOG-"&TEXT(ROW()-2,"00"),"") -> LOG-04 | B6: OBZ Transporte (Carry Over) | C6: DGP / RAI – Estratégico | D6: Transportes | E6: OPEX | F6: Execução Financeira | G6: Helder | H6: Lencione / Helder | I6: L3 | O6: 5.96 | P6: 0.06 | Q6: =IF(M6="","",IF(M6<TODAY(),"⚠️ ATRASADO",IF(M6-TODAY()<30,"⏰ PRÓXIMO","✅ OK"))) | R6: 01/04 - Entregue (2,1). FCST ajustado de 6,9 para 5,9 (aumento combustível) | S6: 02/04 - FCST ajustado em função do aumento do combustível temos impacto na meta
A7: =IF(TabelaPortfolio[[#This Row],[Projeto]]<>"","LOG-"&TEXT(ROW()-2,"00"),"") -> LOG-05 | B7: Venda de Ativo | C7: DGP / RAI – Estratégico | D7: Estoques | E7: OPEX | F7: Execução Financeira | G7: Helder | H7: Gustavo / Estoque | I7: L3 | L7: 46023 | M7: 46357 | N7: 14.027 | O7: 13.907588 | P7: -0.11941243 | Q7: =IF(M7="","",IF(M7<TODAY(),"⚠️ ATRASADO",IF(M7-TODAY()<30,"⏰ PRÓXIMO","✅ OK"))) -> ✅ OK | R7: 02/04 - Entregue 1,26 | S7: 12/03 - FCST atualizado por Gustavo. Obs: na revisão o FCST migra de 14,27 para 14,027
A8: =IF(TabelaPortfolio[[#This Row],[Projeto]]<>"","LOG-"&TEXT(ROW()-2,"00"),"") -> LOG-06 | B8: Projeto Retirada de Equipamento por Regional | C8: DGP / RAI – Estratégico | D8: Desconexão | E8: CAPEX | F8: Execução Financeira | G8: Helder | H8: Dino / Bruno Pires | I8: L0 | L8: 46113 | M8: 46473 | N8: Previsto | O8: 17.402885 | P8: 0 | Q8: =IF(M8="","",IF(M8<TODAY(),"⚠️ ATRASADO",IF(M8-TODAY()<30,"⏰ PRÓXIMO","✅ OK"))) -> ✅ OK | R8: 02/04 - Em validação Dino e Edgar. Seguirá este mês como L0 | S8: Alinhamento com Dino para 31/03 (Atualização do Racional)
A9: =IF(TabelaPortfolio[[#This Row],[Projeto]]<>"","LOG-"&TEXT(ROW()-2,"00"),"") -> LOG-07 | B9: Redução de Controle de Materiais – Estoque dos Técnicos | C9: DGP / RAI – Estratégico | D9: Planejamento | E9: CAPEX | F9: Execução Financeira | G9: Helder | H9: Ademilson / Eder | I9: L1 | N9: 0 | O9: 0 | P9: 0 | Q9: =IF(M9="","",IF(M9<TODAY(),"⚠️ ATRASADO",IF(M9-TODAY()<30,"⏰ PRÓXIMO","✅ OK"))) | R9: 08/04 - Agenda avaliar ações independente TI (16,7) - Agenda 08/04 | S9: 06/04 - Montar proposta para apresentar potencial ganho 2026. R$ 16,7MM (sem previsão captura)
A10: =IF(TabelaPortfolio[[#This Row],[Projeto]]<>"","LOG-"&TEXT(ROW()-2,"00"),"") -> LOG-08 | B10: Massificação eSIM (Saving Logístico) | C10: DGP / RAI – Estratégico | D10: Transportes | E10: OPEX | F10: Execução Financeira | G10: Helder | H10: Lencione / Helder | I10: L1 | L10: 46082 | M10: 46357 | N10: 5.2965344 | O10: 5.2965344 | P10: 0 | Q10: =IF(M10="","",IF(M10<TODAY(),"⚠️ ATRASADO",IF(M10-TODAY()<30,"⏰ PRÓXIMO","✅ OK"))) -> ✅ OK | R10: 10/04 - Agenda semana 10/04 com times de produtos e Financeiro | S10: Ganhos não iniciados. Projeto reportado por produtos
A11: =IF(TabelaPortfolio[[#This Row],[Projeto]]<>"","LOG-"&TEXT(ROW()-2,"00"),"") -> LOG-09 | B11: Unificação Malha Single e Combo Multi | C11: DGP / RAI – Estratégico | D11: Transportes | E11: OPEX | F11: Execução Financeira | G11: Helder | H11: Helder / Edinalva | I11: L1 | L11: 46113 | M11: 46473 | N11: 0.901 | O11: 0.901 | P11: 0 | Q11: =IF(M11="","",IF(M11<TODAY(),"⚠️ ATRASADO",IF(M11-TODAY()<30,"⏰ PRÓXIMO","✅ OK"))) -> ✅ OK | R11: Processo de análise de fornecedores em Compras
A12: =IF(TabelaPortfolio[[#This Row],[Projeto]]<>"","LOG-"&TEXT(ROW()-2,"00"),"") -> LOG-10 | B12: BID Transportes (2026) | C12: DGP / RAI – Estratégico | D12: Transportes | E12: OPEX | F12: Execução Financeira | G12: Helder | H12: Lencione / Helder | I12: L1 | L12: 46204 | M12: 46564 | N12: 1.286 | O12: 1.286 | P12: 0 | Q12: =IF(M12="","",IF(M12<TODAY(),"⚠️ ATRASADO",IF(M12-TODAY()<30,"⏰ PRÓXIMO","✅ OK"))) -> ✅ OK | R12: Processo em contratação de consultoria
A13: =IF(TabelaPortfolio[[#This Row],[Projeto]]<>"","LOG-"&TEXT(ROW()-2,"00"),"") -> LOG-11 | B13: Reversa de Acessórios (controles e fontes) | C13: DGP / RAI – Estratégico | D13: Estoques | E13: CAPEX | F13: Execução Financeira | G13: Helder | H13: Demis / Evandro | I13: L0 | L13: 46023 | M13: 46387 | N13: 0 | O13: 0 | P13: 0 | Q13: =IF(M13="","",IF(M13<TODAY(),"⚠️ ATRASADO",IF(M13-TODAY()<30,"⏰ PRÓXIMO","✅ OK"))) -> ✅ OK | R13: 07/04 - Fechamento do racional (Qtde x Vlr)
A14: =IF(TabelaPortfolio[[#This Row],[Projeto]]<>"","LOG-"&TEXT(ROW()-2,"00"),"") -> LOG-12 | B14: Backlog – LOG Controle Remoto (Ademilson) | C14: DGP / RAI – Estratégico | D14: Planejamento | E14: CAPEX | F14: Execução Financeira | G14: Helder | H14: Ademilson / Rodrigo | I14: L0 | L14: 46023 | M14: 46387 | N14: 0 | O14: 0 | P14: 0 | Q14: =IF(M14="","",IF(M14<TODAY(),"⚠️ ATRASADO",IF(M14-TODAY()<30,"⏰ PRÓXIMO","✅ OK"))) -> ✅ OK | R14: 10/04 - BPLAN em criação. Saving compras 3,13 | S14: 07/04 - Ademilsom e Rodrigo montando racional
A15: =IF(TabelaPortfolio[[#This Row],[Projeto]]<>"","LOG-"&TEXT(ROW()-2,"00"),"") -> LOG-13 | B15: Ciclo de Vida do Equipamento | C15: Operação Logística | D15: Estoques | E15: OPEX | F15: Acompanhamento | G15: Wagner | H15: Gustavo / Estoque | I15: L1 | J15: 🟡 Atenção | K15: Média | L15: 46023 | M15: 46357 | Q15: =IF(M15="","",IF(M15<TODAY(),"⚠️ ATRASADO",IF(M15-TODAY()<30,"⏰ PRÓXIMO","✅ OK"))) -> ✅ OK
A16: =IF(TabelaPortfolio[[#This Row],[Projeto]]<>"","LOG-"&TEXT(ROW()-2,"00"),"") -> LOG-14 | B16: RAI de Estoques – Planos para Redução | C16: Operação Logística | D16: Estoques | E16: OPEX | F16: Acompanhamento | G16: Wagner | H16: Gustavo / Estoque | I16: L1 | J16: 🟡 Atenção | K16: Alta | L16: 46023 | M16: 46357 | Q16: =IF(M16="","",IF(M16<TODAY(),"⚠️ ATRASADO",IF(M16-TODAY()<30,"⏰ PRÓXIMO","✅ OK"))) -> ✅ OK
A17: =IF(TabelaPortfolio[[#This Row],[Projeto]]<>"","LOG-"&TEXT(ROW()-2,"00"),"") -> LOG-15 | B17: Parqueamento e Milk Run | C17: Operação Logística | D17: Transportes | E17: OPEX | F17: Execução | G17: Helder | H17: Leandro / Lencione | I17: L1 | J17: 🟢 Em Dia | K17: Média | L17: 46054 | M17: 46387 | Q17: =IF(M17="","",IF(M17<TODAY(),"⚠️ ATRASADO",IF(M17-TODAY()<30,"⏰ PRÓXIMO","✅ OK"))) -> ✅ OK
A18: =IF(TabelaPortfolio[[#This Row],[Projeto]]<>"","LOG-"&TEXT(ROW()-2,"00"),"") -> LOG-16 | B18: Calendarização, Roteirização e Capilaridade | C18: Operação Logística | D18: Planejamento | E18: OPEX | F18: Execução | H18: Leandro / Maiello | I18: L2 | J18: 🟢 Em Dia | K18: Alta | L18: 46054 | M18: 46387 | Q18: =IF(M18="","",IF(M18<TODAY(),"⚠️ ATRASADO",IF(M18-TODAY()<30,"⏰ PRÓXIMO","✅ OK"))) -> ✅ OK
A19: =IF(TabelaPortfolio[[#This Row],[Projeto]]<>"","LOG-"&TEXT(ROW()-2,"00"),"") -> LOG-17 | B19: Distribuição e Pedido Mínimo | C19: Operação Logística | D19: Planejamento | E19: OPEX | F19: Execução | H19: Leandro / Planejamento | I19: L1 | J19: 🟢 Em Dia | K19: Média | L19: 46082 | M19: 46357 | Q19: =IF(M19="","",IF(M19<TODAY(),"⚠️ ATRASADO",IF(M19-TODAY()<30,"⏰ PRÓXIMO","✅ OK"))) -> ✅ OK
A20: =IF(TabelaPortfolio[[#This Row],[Projeto]]<>"","LOG-"&TEXT(ROW()-2,"00"),"") -> LOG-18 | B20: Redução de Consumo de Materiais | C20: Operação Logística | D20: Estoques | E20: OPEX | F20: Acompanhamento | G20: Wagner | H20: Gustavo / Estoque | I20: L2 | J20: 🟢 Em Dia | K20: Alta | L20: 46082 | M20: 46357 | Q20: =IF(M20="","",IF(M20<TODAY(),"⚠️ ATRASADO",IF(M20-TODAY()<30,"⏰ PRÓXIMO","✅ OK"))) -> ✅ OK
A21: =IF(TabelaPortfolio[[#This Row],[Projeto]]<>"","LOG-"&TEXT(ROW()-2,"00"),"") -> LOG-19 | B21: Empresarial – Aumento da Logística Reversa | C21: Operação Logística | D21: Desconexão | E21: OPEX | F21: Execução | H21: Dino / Desconexão | I21: L1 | J21: 🟢 Em Dia | K21: Média | L21: 46023 | M21: 46387 | Q21: =IF(M21="","",IF(M21<TODAY(),"⚠️ ATRASADO",IF(M21-TODAY()<30,"⏰ PRÓXIMO","✅ OK"))) -> ✅ OK
A22: =IF(TabelaPortfolio[[#This Row],[Projeto]]<>"","LOG-"&TEXT(ROW()-2,"00"),"") -> LOG-20 | B22: Estoque Empresarial – Uso de Sobressalente | C22: Operação Logística | D22: Estoques | E22: CAPEX | F22: Execução | G22: Wagner | H22: Gustavo / Eduardo | I22: L1 | J22: 🟢 Em Dia | K22: Média | L22: 46023 | M22: 46387 | Q22: =IF(M22="","",IF(M22<TODAY(),"⚠️ ATRASADO",IF(M22-TODAY()<30,"⏰ PRÓXIMO","✅ OK"))) -> ✅ OK
A23: =IF(TabelaPortfolio[[#This Row],[Projeto]]<>"","LOG-"&TEXT(ROW()-2,"00"),"") -> LOG-21 | B23: Gestão de Risco | C23: Operação Logística | D23: Planejamento | E23: OPEX | F23: Acompanhamento | H23: Ingrid / Planejamento | I23: L2 | J23: 🟢 Em Dia | K23: Alta | L23: 46113 | M23: 46387 | Q23: =IF(M23="","",IF(M23<TODAY(),"⚠️ ATRASADO",IF(M23-TODAY()<30,"⏰ PRÓXIMO","✅ OK"))) -> ✅ OK
A24: =IF(TabelaPortfolio[[#This Row],[Projeto]]<>"","LOG-"&TEXT(ROW()-2,"00"),"") -> LOG-22 | B24: Reduzir a Utilização dos Correios | C24: Operação Logística | D24: Transportes | E24: OPEX | F24: Execução | G24: Helder | H24: Leandro / Lencione | I24: L2 | J24: 🟢 Em Dia | K24: Alta | L24: 46113 | M24: 46387 | Q24: =IF(M24="","",IF(M24<TODAY(),"⚠️ ATRASADO",IF(M24-TODAY()<30,"⏰ PRÓXIMO","✅ OK"))) -> ✅ OK
A25: =IF(TabelaPortfolio[[#This Row],[Projeto]]<>"","LOG-"&TEXT(ROW()-2,"00"),"") -> LOG-23 | B25: BID de Transportes | C25: Operação Logística | D25: Transportes | E25: OPEX | F25: Execução | G25: Helder | H25: Lencione / Helder | I25: L1 | J25: 🟢 Em Dia | K25: Alta | L25: 46143 | M25: 46387 | Q25: =IF(M25="","",IF(M25<TODAY(),"⚠️ ATRASADO",IF(M25-TODAY()<30,"⏰ PRÓXIMO","✅ OK"))) -> ✅ OK
A26: =IF(TabelaPortfolio[[#This Row],[Projeto]]<>"","LOG-"&TEXT(ROW()-2,"00"),"") -> LOG-24 | B26: Unificação de Entregas Logísticas (Chip) | C26: Operação Logística | D26: Transportes | E26: OPEX | F26: Execução | H26: Helder / Edinalva | I26: L1 | J26: 🟢 Em Dia | K26: Média | L26: 46143 | M26: 46387 | Q26: =IF(M26="","",IF(M26<TODAY(),"⚠️ ATRASADO",IF(M26-TODAY()<30,"⏰ PRÓXIMO","✅ OK"))) -> ✅ OK
A27: =IF(TabelaPortfolio[[#This Row],[Projeto]]<>"","LOG-"&TEXT(ROW()-2,"00"),"") -> LOG-25 | B27: Ampliação do eSIM | C27: Operação Logística | D27: Transportes | E27: OPEX | F27: Execução Financeira | G27: Helder | H27: Lencione / Helder | I27: L1 | J27: 🟢 Em Dia | K27: Média | L27: 46054 | M27: 46357 | Q27: =IF(M27="","",IF(M27<TODAY(),"⚠️ ATRASADO",IF(M27-TODAY()<30,"⏰ PRÓXIMO","✅ OK"))) -> ✅ OK
A28: =IF(TabelaPortfolio[[#This Row],[Projeto]]<>"","LOG-"&TEXT(ROW()-2,"00"),"") -> LOG-26 | B28: Torre de Comando (Gestor de Alertas Beon) | C28: Operação Logística | D28: Planejamento | E28: OPEX | F28: Execução | H28: Marcelo / Ingrid | I28: L0 | J28: 🟡 Atenção | K28: Alta | L28: 46082 | M28: 46387 | Q28: =IF(M28="","",IF(M28<TODAY(),"⚠️ ATRASADO",IF(M28-TODAY()<30,"⏰ PRÓXIMO","✅ OK"))) -> ✅ OK
A29: =IF(TabelaPortfolio[[#This Row],[Projeto]]<>"","LOG-"&TEXT(ROW()-2,"00"),"") -> LOG-27 | B29: Inventário Automatizado de Equipamentos | C29: Operação Logística | D29: Estoques | E29: CAPEX | F29: Execução | G29: Wagner | H29: Eduardo Cruz / Estoque | I29: L0 | J29: 🟡 Atenção | K29: Média | L29: 46113 | M29: 46387 | Q29: =IF(M29="","",IF(M29<TODAY(),"⚠️ ATRASADO",IF(M29-TODAY()<30,"⏰ PRÓXIMO","✅ OK"))) -> ✅ OK
A30: =IF(TabelaPortfolio[[#This Row],[Projeto]]<>"","LOG-"&TEXT(ROW()-2,"00"),"") -> LOG-28 | B30: Inversão da Esteira Logística (TSP x CD) | C30: Operação Logística | D30: Planejamento | E30: OPEX | F30: Execução | H30: Leandro / Planejamento | I30: L1 | J30: 🟢 Em Dia | K30: Média | L30: 46023 | M30: 46357 | Q30: =IF(M30="","",IF(M30<TODAY(),"⚠️ ATRASADO",IF(M30-TODAY()<30,"⏰ PRÓXIMO","✅ OK"))) -> ✅ OK
A31: =IF(TabelaPortfolio[[#This Row],[Projeto]]<>"","LOG-"&TEXT(ROW()-2,"00"),"") -> LOG-29 | B31: Esteira da Reversa (operação, velocidade, qualidade) | C31: Operação Logística | D31: Desconexão | E31: OPEX | F31: Execução | H31: Dino / Guimarães | I31: L2 | J31: 🟢 Em Dia | K31: Alta | L31: 46054 | M31: 46387 | Q31: =IF(M31="","",IF(M31<TODAY(),"⚠️ ATRASADO",IF(M31-TODAY()<30,"⏰ PRÓXIMO","✅ OK"))) -> ✅ OK
A32: =IF(TabelaPortfolio[[#This Row],[Projeto]]<>"","LOG-"&TEXT(ROW()-2,"00"),"") -> LOG-30 | B32: Automatização e Robotização de CDs | C32: Operação Logística | D32: Planejamento | E32: CAPEX | F32: Execução | H32: Paulo Quinete / CDs | I32: L0 | J32: 🟡 Atenção | K32: Alta | L32: 46174 | M32: 46387 | Q32: =IF(M32="","",IF(M32<TODAY(),"⚠️ ATRASADO",IF(M32-TODAY()<30,"⏰ PRÓXIMO","✅ OK"))) -> ✅ OK
A33: =IF(TabelaPortfolio[[#This Row],[Projeto]]<>"","LOG-"&TEXT(ROW()-2,"00"),"") -> LOG-31 | B33: Ampliação da Ecobox | C33: Operação Logística | D33: Desconexão | E33: OPEX | F33: Execução | H33: Dino / Ismael | I33: L1 | J33: 🟢 Em Dia | K33: Média | L33: 46082 | M33: 46357 | Q33: =IF(M33="","",IF(M33<TODAY(),"⚠️ ATRASADO",IF(M33-TODAY()<30,"⏰ PRÓXIMO","✅ OK"))) -> ✅ OK
A34: =IF(TabelaPortfolio[[#This Row],[Projeto]]<>"","LOG-"&TEXT(ROW()-2,"00"),"") -> LOG-32 | B34: Revisão da Malha Logística (Reforma Tributária) | C34: Operação Logística | D34: Planejamento | E34: OPEX | F34: Acompanhamento | H34: Marcelo / Matheus | I34: L1 | J34: 🟢 Em Dia | K34: Alta | L34: 46113 | M34: 46387 | Q34: =IF(M34="","",IF(M34<TODAY(),"⚠️ ATRASADO",IF(M34-TODAY()<30,"⏰ PRÓXIMO","✅ OK"))) -> ✅ OK
A35: =IF(TabelaPortfolio[[#This Row],[Projeto]]<>"","LOG-"&TEXT(ROW()-2,"00"),"") -> LOG-33 | B35: Controle de Estoque no Técnico | C35: Operação Logística | D35: Estoques | E35: CAPEX | F35: Execução | G35: Helder | H35: Fabiana Pons / Eder Rocha | I35: L1 | J35: 🟢 Em Dia | K35: Média | L35: 46023 | M35: 46357 | Q35: =IF(M35="","",IF(M35<TODAY(),"⚠️ ATRASADO",IF(M35-TODAY()<30,"⏰ PRÓXIMO","✅ OK"))) -> ✅ OK
A36: =IF(TabelaPortfolio[[#This Row],[Projeto]]<>"","LOG-"&TEXT(ROW()-2,"00"),"") -> LOG-34 | B36: FORECAST x Real – IBP | C36: Operação Logística | D36: Planejamento | E36: OPEX | F36: Execução | H36: Ingrid / Planejamento | I36: L2 | J36: 🟢 Em Dia | K36: Média | L36: 46143 | M36: 46387 | Q36: =IF(M36="","",IF(M36<TODAY(),"⚠️ ATRASADO",IF(M36-TODAY()<30,"⏰ PRÓXIMO","✅ OK"))) -> ✅ OK
A37: =IF(TabelaPortfolio[[#This Row],[Projeto]]<>"","LOG-"&TEXT(ROW()-2,"00"),"") -> LOG-35 | B37: Retorno de Acessórios / Partes e Peças | C37: Operação Logística | D37: Desconexão | E37: CAPEX | F37: Execução | H37: Dino / Desconexão | I37: L1 | J37: 🟢 Em Dia | K37: Média | L37: 46054 | M37: 46357 | Q37: =IF(M37="","",IF(M37<TODAY(),"⚠️ ATRASADO",IF(M37-TODAY()<30,"⏰ PRÓXIMO","✅ OK"))) -> ✅ OK
A38: =IF(TabelaPortfolio[[#This Row],[Projeto]]<>"","LOG-"&TEXT(ROW()-2,"00"),"") -> LOG-36 | B38: Montagem de Kits no CD na Reversa | C38: Operação Logística | D38: Desconexão | E38: OPEX | F38: Execução | H38: Dino / Desconexão | I38: L1 | J38: 🟢 Em Dia | K38: Baixa | L38: 46082 | M38: 46357 | Q38: =IF(M38="","",IF(M38<TODAY(),"⚠️ ATRASADO",IF(M38-TODAY()<30,"⏰ PRÓXIMO","✅ OK"))) -> ✅ OK
A39: =IF(TabelaPortfolio[[#This Row],[Projeto]]<>"","LOG-"&TEXT(ROW()-2,"00"),"") -> LOG-37 | B39: Controle de Estoque PEP | C39: Operação Logística | D39: Estoques | E39: OPEX | F39: Execução | G39: Wagner | H39: Mateus Barbeiro | I39: L1 | J39: 🟢 Em Dia | K39: Média | L39: 46023 | M39: 46357 | Q39: =IF(M39="","",IF(M39<TODAY(),"⚠️ ATRASADO",IF(M39-TODAY()<30,"⏰ PRÓXIMO","✅ OK"))) -> ✅ OK
A40: =IF(TabelaPortfolio[[#This Row],[Projeto]]<>"","LOG-"&TEXT(ROW()-2,"00"),"") -> LOG-38 | B40: App Devolução de Lojas / AAs | C40: Operação Logística | D40: Desconexão | E40: OPEX | F40: Acompanhamento | G40: Helder | H40: Dino / Ismael | I40: L2 | J40: 🟢 Em Dia | K40: Alta | L40: 46113 | M40: 46387 | Q40: =IF(M40="","",IF(M40<TODAY(),"⚠️ ATRASADO",IF(M40-TODAY()<30,"⏰ PRÓXIMO","✅ OK"))) -> ✅ OK
...
